<?xml version='1.0' encoding='utf-8'?>
<sdf version="1.8">
    <model name="vehicle_blue" canonical_link="base_link">
        <pose>0 0 0 0 0 0</pose>

        <!-- 底盘 -->
        <link name="base_link">
            <pose relative_to="__model__">0.5 0 0.4 0 0 0</pose>
            <inertial>
                <mass>1.14395</mass>
                <inertia>
                    <ixx>0.095329</ixx>
                    <ixy>0</ixy>
                    <ixz>0</ixz>
                    <iyy>0.381317</iyy>
                    <iyz>0</iyz>
                    <izz>0.476646</izz>
                </inertia>
            </inertial>
            <visual name="visual">
                <geometry>
                    <box>
                        <size>2.0 1.0 0.5</size>
                    </box>
                </geometry>
                <material>
                    <ambient>0.0 0.0 1.0 1</ambient>
                    <diffuse>0.0 0.0 1.0 1</diffuse>
                    <specular>0.0 0.0 1.0 1</specular>
                </material>
            </visual>
            <collision name="collision">
                <geometry>
                    <box>
                        <size>2.0 1.0 0.5</size>
                    </box>
                </geometry>
            </collision>
            <sensor name="imu_sensor" type="imu">
                <always_on>1</always_on>
                <update_rate>200</update_rate>
                <visualize>true</visualize>
                <topic>imu</topic>
            </sensor>
            <sensor name='sensor_contact' type='contact'>
                <contact>
                    <collision>collision</collision>
                </contact>
            </sensor>
            <sensor name='gpu_lidar' type='gpu_lidar'>
                <pose relative_to='base_lidar'>0 0 0 0 0 0</pose>
                <topic>lidar</topic>
                <update_rate>10</update_rate>
                <ray>
                    <scan>
                        <horizontal>
                            <samples>1500.0</samples>
                            <resolution>1.0</resolution>
                            <min_angle>0</min_angle>
                            <max_angle>6.2831852</max_angle>
                        </horizontal>
                        <vertical>
                            <samples>32</samples>
                            <min_angle>-0.12217304764</min_angle>
                            <max_angle>0.90757121104</max_angle>
                        </vertical>
                    </scan>
                    <range>
                        <min>0.08</min>
                        <max>10.0</max>
                        <resolution>0.01</resolution>
                    </range>
                </ray>
                <always_on>1</always_on>
                <visualize>true</visualize>
            </sensor>
        </link>

        <!-- 左轮（红色） -->
        <link name="left_wheel">
            <pose relative_to="base_link">-0.5 0.6 0 -1.5707 0 0</pose>
            <inertial>
                <mass>1</mass>
                <inertia>
                    <ixx>0.043333</ixx>
                    <ixy>0</ixy>
                    <ixz>0</ixz>
                    <iyy>0.043333</iyy>
                    <iyz>0</iyz>
                    <izz>0.08</izz>
                </inertia>
            </inertial>
            <visual name="visual">
                <geometry>
                    <cylinder>
                        <radius>0.4</radius>
                        <length>0.2</length>
                    </cylinder>
                </geometry>
                <material>
                    <ambient>1.0 0.0 0.0 1</ambient>
                    <diffuse>1.0 0.0 0.0 1</diffuse>
                    <specular>1.0 0.0 0.0 1</specular>
                </material>
            </visual>
            <collision name="collision">
                <geometry>
                    <cylinder>
                        <radius>0.4</radius>
                        <length>0.2</length>
                    </cylinder>
                </geometry>
            </collision>
        </link>

        <!-- 右轮（红色） -->
        <link name="right_wheel">
            <pose relative_to="base_link">-0.5 -0.6 0 -1.5707 0 0</pose>
            <inertial>
                <mass>1</mass>
                <inertia>
                    <ixx>0.043333</ixx>
                    <ixy>0</ixy>
                    <ixz>0</ixz>
                    <iyy>0.043333</iyy>
                    <iyz>0</iyz>
                    <izz>0.08</izz>
                </inertia>
            </inertial>
            <visual name="visual">
                <geometry>
                    <cylinder>
                        <radius>0.4</radius>
                        <length>0.2</length>
                    </cylinder>
                </geometry>
                <material>
                    <ambient>1.0 0.0 0.0 1</ambient>
                    <diffuse>1.0 0.0 0.0 1</diffuse>
                    <specular>1.0 0.0 0.0 1</specular>
                </material>
            </visual>
            <collision name="collision">
                <geometry>
                    <cylinder>
                        <radius>0.4</radius>
                        <length>0.2</length>
                    </cylinder>
                </geometry>
            </collision>
        </link>

        <!-- 脚轮（绿色） -->
        <frame name="caster_frame" attached_to="base_link">
            <pose>0.8 0 -0.2 0 0 0</pose>
        </frame>
        <link name="caster">
            <pose relative_to="caster_frame" />
            <inertial>
                <mass>1</mass>
                <inertia>
                    <ixx>0.016</ixx>
                    <ixy>0</ixy>
                    <ixz>0</ixz>
                    <iyy>0.016</iyy>
                    <iyz>0</iyz>
                    <izz>0.016</izz>
                </inertia>
            </inertial>
            <visual name="visual">
                <geometry>
                    <sphere>
                        <radius>0.2</radius>
                    </sphere>
                </geometry>
                <material>
                    <ambient>0.0 1.0 0.0 1</ambient>
                    <diffuse>0.0 1.0 0.0 1</diffuse>
                    <specular>0.0 1.0 0.0 1</specular>
                </material>
            </visual>
            <collision name="collision">
                <geometry>
                    <sphere>
                        <radius>0.2</radius>
                    </sphere>
                </geometry>
            </collision>
        </link>

        <!-- 关节定义 -->
        <joint name="left_wheel_joint" type="revolute">
            <pose relative_to="left_wheel" />
            <parent>base_link</parent>
            <child>left_wheel</child>
            <axis>
                <xyz expressed_in="__model__">0 1 0</xyz>
                <limit>
                    <lower>-1.79769e+308</lower>
                    <upper>1.79769e+308</upper>
                </limit>
            </axis>
        </joint>

        <joint name="right_wheel_joint" type="revolute">
            <pose relative_to="right_wheel" />
            <parent>base_link</parent>
            <child>right_wheel</child>
            <axis>
                <xyz expressed_in="__model__">0 1 0</xyz>
                <limit>
                    <lower>-1.79769e+308</lower>
                    <upper>1.79769e+308</upper>
                </limit>
            </axis>
        </joint>

        <joint name="caster_wheel" type="ball">
            <parent>base_link</parent>
            <child>caster</child>
        </joint>

        <!-- 差速驱动插件 -->
        <plugin filename="libignition-gazebo-diff-drive-system.so"
            name="ignition::gazebo::systems::DiffDrive">
            <left_joint>left_wheel_joint</left_joint>
            <right_joint>right_wheel_joint</right_joint>
            <wheel_separation>1.2</wheel_separation>
            <wheel_radius>0.4</wheel_radius>
            <odom_publish_frequency>1</odom_publish_frequency>
            <topic>cmd_vel</topic>
        </plugin>

        <!-- 碰撞检测插件 -->
        <plugin filename="libignition-gazebo-touchplugin-system.so"
            name="ignition::gazebo::systems::TouchPlugin">
            <target>vehicle_blue</target>
            <namespace>wall</namespace>
            <time>0.001</time>
            <enabled>true</enabled>
        </plugin>

        <!-- 激光雷达坐标系 -->
        <frame name="base_lidar" attached_to='base_link'>
            <pose>0.8 0 0.5 0 0 0</pose>
        </frame>
    </model>

            <!-- 3. 键盘控制插件（通过按键发布速度指令） -->
        <!-- 前进（对应键盘按键：上箭头） -->
        <plugin 
            filename="libignition-gazebo-triggered-publisher-system.so"
            name="ignition::gazebo::systems::TriggeredPublisher">
            <input type="ignition.msgs.Int32" topic="/keyboard/keypress">
                <match field="data">16777235</match>
            </input>
            <output type="ignition.msgs.Twist" topic="/cmd_vel">
                linear: {x: 0.5}, angular: {z: 0.0}
            </output>
        </plugin>

        <!-- 后退（对应键盘按键：下箭头） -->
        <plugin 
            filename="libignition-gazebo-triggered-publisher-system.so"
            name="ignition::gazebo::systems::TriggeredPublisher">
            <input type="ignition.msgs.Int32" topic="/keyboard/keypress">
                <match field="data">16777237</match>
            </input>
            <output type="ignition.msgs.Twist" topic="/cmd_vel">
                linear: {x: -0.5}, angular: {z: 0.0}
            </output>
        </plugin>

        <!-- 左转（对应键盘按键：左箭头） -->
        <plugin 
            filename="libignition-gazebo-triggered-publisher-system.so"
            name="ignition::gazebo::systems::TriggeredPublisher">
            <input type="ignition.msgs.Int32" topic="/keyboard/keypress">
                <match field="data">16777234</match>
            </input>
            <output type="ignition.msgs.Twist" topic="/cmd_vel">
                linear: {x: 0.0}, angular: {z: 0.5}
            </output>
        </plugin>

        <!-- 右转（对应键盘按键：右箭头） -->
        <plugin 
            filename="libignition-gazebo-triggered-publisher-system.so"
            name="ignition::gazebo::systems::TriggeredPublisher">
            <input type="ignition.msgs.Int32" topic="/keyboard/keypress">
                <match field="data">16777236</match>
            </input>
            <output type="ignition.msgs.Twist" topic="/cmd_vel">
                linear: {x: 0.0}, angular: {z: -0.5}
            </output>
        </plugin>
</sdf>
